2018-10-12 11:22:34,327 INFO: Microblog startup [in C:\Users\Konstantin\projects\microblog\myapp\__init__.py:44]
2018-10-12 11:23:51,860 ERROR: Exception on /edit_profile [POST] [in c:\users\konstantin\projects\microblog\venv\lib\site-packages\flask\app.py:1761]
Traceback (most recent call last):
  File "c:\users\konstantin\projects\microblog\venv\lib\site-packages\sqlalchemy\engine\base.py", line 1193, in _execute_context
    context)
  File "c:\users\konstantin\projects\microblog\venv\lib\site-packages\sqlalchemy\engine\default.py", line 509, in do_execute
    cursor.execute(statement, parameters)
sqlite3.IntegrityError: UNIQUE constraint failed: user.username

The above exception was the direct cause of the following exception:

Traceback (most recent call last):
  File "c:\users\konstantin\projects\microblog\venv\lib\site-packages\flask\app.py", line 2292, in wsgi_app
    response = self.full_dispatch_request()
  File "c:\users\konstantin\projects\microblog\venv\lib\site-packages\flask\app.py", line 1815, in full_dispatch_request
    rv = self.handle_user_exception(e)
  File "c:\users\konstantin\projects\microblog\venv\lib\site-packages\flask\app.py", line 1718, in handle_user_exception
    reraise(exc_type, exc_value, tb)
  File "c:\users\konstantin\projects\microblog\venv\lib\site-packages\flask\_compat.py", line 35, in reraise
    raise value
  File "c:\users\konstantin\projects\microblog\venv\lib\site-packages\flask\app.py", line 1813, in full_dispatch_request
    rv = self.dispatch_request()
  File "c:\users\konstantin\projects\microblog\venv\lib\site-packages\flask\app.py", line 1799, in dispatch_request
    return self.view_functions[rule.endpoint](**req.view_args)
  File "c:\users\konstantin\projects\microblog\venv\lib\site-packages\flask_login\utils.py", line 261, in decorated_view
    return func(*args, **kwargs)
  File "C:\Users\Konstantin\projects\microblog\myapp\routes.py", line 98, in edit_profile
    db.session.commit()
  File "c:\users\konstantin\projects\microblog\venv\lib\site-packages\sqlalchemy\orm\scoping.py", line 153, in do
    return getattr(self.registry(), name)(*args, **kwargs)
  File "c:\users\konstantin\projects\microblog\venv\lib\site-packages\sqlalchemy\orm\session.py", line 943, in commit
    self.transaction.commit()
  File "c:\users\konstantin\projects\microblog\venv\lib\site-packages\sqlalchemy\orm\session.py", line 467, in commit
    self._prepare_impl()
  File "c:\users\konstantin\projects\microblog\venv\lib\site-packages\sqlalchemy\orm\session.py", line 447, in _prepare_impl
    self.session.flush()
  File "c:\users\konstantin\projects\microblog\venv\lib\site-packages\sqlalchemy\orm\session.py", line 2254, in flush
    self._flush(objects)
  File "c:\users\konstantin\projects\microblog\venv\lib\site-packages\sqlalchemy\orm\session.py", line 2380, in _flush
    transaction.rollback(_capture_exception=True)
  File "c:\users\konstantin\projects\microblog\venv\lib\site-packages\sqlalchemy\util\langhelpers.py", line 66, in __exit__
    compat.reraise(exc_type, exc_value, exc_tb)
  File "c:\users\konstantin\projects\microblog\venv\lib\site-packages\sqlalchemy\util\compat.py", line 249, in reraise
    raise value
  File "c:\users\konstantin\projects\microblog\venv\lib\site-packages\sqlalchemy\orm\session.py", line 2344, in _flush
    flush_context.execute()
  File "c:\users\konstantin\projects\microblog\venv\lib\site-packages\sqlalchemy\orm\unitofwork.py", line 391, in execute
    rec.execute(self)
  File "c:\users\konstantin\projects\microblog\venv\lib\site-packages\sqlalchemy\orm\unitofwork.py", line 556, in execute
    uow
  File "c:\users\konstantin\projects\microblog\venv\lib\site-packages\sqlalchemy\orm\persistence.py", line 177, in save_obj
    mapper, table, update)
  File "c:\users\konstantin\projects\microblog\venv\lib\site-packages\sqlalchemy\orm\persistence.py", line 768, in _emit_update_statements
    execute(statement, multiparams)
  File "c:\users\konstantin\projects\microblog\venv\lib\site-packages\sqlalchemy\engine\base.py", line 948, in execute
    return meth(self, multiparams, params)
  File "c:\users\konstantin\projects\microblog\venv\lib\site-packages\sqlalchemy\sql\elements.py", line 269, in _execute_on_connection
    return connection._execute_clauseelement(self, multiparams, params)
  File "c:\users\konstantin\projects\microblog\venv\lib\site-packages\sqlalchemy\engine\base.py", line 1060, in _execute_clauseelement
    compiled_sql, distilled_params
  File "c:\users\konstantin\projects\microblog\venv\lib\site-packages\sqlalchemy\engine\base.py", line 1200, in _execute_context
    context)
  File "c:\users\konstantin\projects\microblog\venv\lib\site-packages\sqlalchemy\engine\base.py", line 1413, in _handle_dbapi_exception
    exc_info
  File "c:\users\konstantin\projects\microblog\venv\lib\site-packages\sqlalchemy\util\compat.py", line 265, in raise_from_cause
    reraise(type(exception), exception, tb=exc_tb, cause=cause)
  File "c:\users\konstantin\projects\microblog\venv\lib\site-packages\sqlalchemy\util\compat.py", line 248, in reraise
    raise value.with_traceback(tb)
  File "c:\users\konstantin\projects\microblog\venv\lib\site-packages\sqlalchemy\engine\base.py", line 1193, in _execute_context
    context)
  File "c:\users\konstantin\projects\microblog\venv\lib\site-packages\sqlalchemy\engine\default.py", line 509, in do_execute
    cursor.execute(statement, parameters)
sqlalchemy.exc.IntegrityError: (sqlite3.IntegrityError) UNIQUE constraint failed: user.username [SQL: 'UPDATE user SET username=?, about_me=? WHERE user.id = ?'] [parameters: ('valstad', "I'm a cat", 2)] (Background on this error at: http://sqlalche.me/e/gkpj)
2018-10-12 11:39:07,383 INFO: Microblog startup [in C:\Users\Konstantin\projects\microblog\myapp\__init__.py:45]
2018-10-12 11:39:30,876 ERROR: Exception on /edit_profile [POST] [in c:\users\konstantin\projects\microblog\venv\lib\site-packages\flask\app.py:1761]
Traceback (most recent call last):
  File "c:\users\konstantin\projects\microblog\venv\lib\site-packages\flask\app.py", line 2292, in wsgi_app
    response = self.full_dispatch_request()
  File "c:\users\konstantin\projects\microblog\venv\lib\site-packages\flask\app.py", line 1815, in full_dispatch_request
    rv = self.handle_user_exception(e)
  File "c:\users\konstantin\projects\microblog\venv\lib\site-packages\flask\app.py", line 1718, in handle_user_exception
    reraise(exc_type, exc_value, tb)
  File "c:\users\konstantin\projects\microblog\venv\lib\site-packages\flask\_compat.py", line 35, in reraise
    raise value
  File "c:\users\konstantin\projects\microblog\venv\lib\site-packages\flask\app.py", line 1813, in full_dispatch_request
    rv = self.dispatch_request()
  File "c:\users\konstantin\projects\microblog\venv\lib\site-packages\flask\app.py", line 1799, in dispatch_request
    return self.view_functions[rule.endpoint](**req.view_args)
  File "c:\users\konstantin\projects\microblog\venv\lib\site-packages\flask_login\utils.py", line 261, in decorated_view
    return func(*args, **kwargs)
  File "C:\Users\Konstantin\projects\microblog\myapp\routes.py", line 95, in edit_profile
    if form.validate_on_submit():
  File "c:\users\konstantin\projects\microblog\venv\lib\site-packages\flask_wtf\form.py", line 101, in validate_on_submit
    return self.is_submitted() and self.validate()
  File "c:\users\konstantin\projects\microblog\venv\lib\site-packages\wtforms\form.py", line 310, in validate
    return super(Form, self).validate(extra)
  File "c:\users\konstantin\projects\microblog\venv\lib\site-packages\wtforms\form.py", line 152, in validate
    if not field.validate(self, extra):
  File "c:\users\konstantin\projects\microblog\venv\lib\site-packages\wtforms\fields\core.py", line 206, in validate
    stop_validation = self._run_validation_chain(form, chain)
  File "c:\users\konstantin\projects\microblog\venv\lib\site-packages\wtforms\fields\core.py", line 226, in _run_validation_chain
    validator(form, self)
  File "C:\Users\Konstantin\projects\microblog\myapp\forms.py", line 46, in validate_username
    raise ValidatorError('Please use a different username.')
NameError: name 'ValidatorError' is not defined
2018-10-12 11:40:11,717 INFO: Microblog startup [in C:\Users\Konstantin\projects\microblog\myapp\__init__.py:45]
2018-10-12 12:29:49,512 INFO: Microblog startup [in C:\Users\Konstantin\projects\microblog\myapp\__init__.py:45]
2018-10-12 12:30:36,437 INFO: Microblog startup [in C:\Users\Konstantin\projects\microblog\myapp\__init__.py:45]
2018-10-12 12:30:55,079 INFO: Microblog startup [in C:\Users\Konstantin\projects\microblog\myapp\__init__.py:45]
2018-10-12 12:31:13,909 INFO: Microblog startup [in C:\Users\Konstantin\projects\microblog\myapp\__init__.py:45]
2018-10-12 12:31:40,273 INFO: Microblog startup [in C:\Users\Konstantin\projects\microblog\myapp\__init__.py:45]
2018-10-12 12:32:20,193 INFO: Microblog startup [in C:\Users\Konstantin\projects\microblog\myapp\__init__.py:45]
2018-10-12 12:32:56,932 INFO: Microblog startup [in C:\Users\Konstantin\projects\microblog\myapp\__init__.py:45]
2018-10-12 12:34:17,834 INFO: Microblog startup [in C:\Users\Konstantin\projects\microblog\myapp\__init__.py:45]
